<?xml version="1.0" ?>
<!-- =================================================================================== -->
<!-- |    This document was autogenerated by xacro from 05_arm_model.xacro             | -->
<!-- |    EDITING THIS FILE BY HAND IS NOT RECOMMENDED                                 | -->
<!-- =================================================================================== -->
<robot name="firefighter" xmlns:xacro="http://www.ros.org/wiki/xacro">
  <link name="base">
    <visual>
      <geometry>
        <!--- 0.0 0 -0.04 -->
        <mesh filename="/home/ewenwan/ewenwan/learn/learn_ros_urdf/UArmForROS/urdf/daes/base.STL"/>
      </geometry>
      <origin rpy=" 1.57 0 3.14159" xyz="0.1 -0.1 0 "/>
      <material name="white">
        <color rgba="0.8 0.8 0.8 0.8"/>
      </material>
    </visual>
  </link>
  <link name="base_rot">
    <visual>
      <geometry>
        <mesh filename="/home/ewenwan/ewenwan/learn/learn_ros_urdf/UArmForROS/urdf/daes/base_rot.dae"/>
        <!--- <cylinder length="0.16" radius="0.02"/>  <! 0.16 0.02 -->
      </geometry>
      <origin rpy=" 0 0 1.57" xyz="0.0 0 0 "/>
      <!--- 0.0 0 -0.04 -->
      <material name="inwhite">
        <color rgba="0.8 0.8 0.8 0.8"/>
      </material>
    </visual>
  </link>
  <link name="link_1">
    <visual>
      <geometry>
        <mesh filename="/home/ewenwan/ewenwan/learn/learn_ros_urdf/UArmForROS/urdf/daes/link_1.dae"/>
        <!---
        <cylinder length="0.14" radius="0.01"/>  <! 0.14 0.01 -->
      </geometry>
      <origin rpy=" 0 1.57 0" xyz="0.0 0 0 "/>
      <!--- 0.07 0 0-->
      <material name="white">

	</material>
    </visual>
  </link>
  <link name="link_2">
    <visual>
      <geometry>
        <mesh filename="/home/ewenwan/ewenwan/learn/learn_ros_urdf/UArmForROS/urdf/daes/link_2.dae"/>
        <!---
        <cylinder length="0.16" radius="0.01"/>  <! 0.16 0.01 -->
      </geometry>
      <origin rpy=" 3.1415 1.57 0" xyz="0.1602 0.005 0"/>
      <!--- 0.08 0 0  -->
      <material name="inwhite">

	</material>
    </visual>
  </link>
  <link name="link_3">
    <visual>
      <geometry>
        <mesh filename="/home/ewenwan/ewenwan/learn/learn_ros_urdf/UArmForROS/urdf/daes/link_3_2.dae"/>
        <!---
        <cylinder length="0.04" radius="0.01"/>  <! 0.04 0.01 -->
      </geometry>
      <origin rpy=" 0 1.57 0" xyz="0.0 0 0"/>
      <!--- 0.02 0 0 -->
      <material name="white">

	</material>
    </visual>
  </link>
  <link name="link_end">
    <visual>
      <geometry>
        <mesh filename="/home/ewenwan/ewenwan/learn/learn_ros_urdf/UArmForROS/urdf/daes/link_end_2.dae"/>
        <!---
        <cylinder length="0.05" radius="0.005"/>  <! 0.05 0.005 -->
      </geometry>
      <origin rpy=" 0 0 0" xyz="0.0 0 0"/>
      <!--- 0 0 0.025 -->
      <material name="inwhite">

	  </material>
    </visual>
  </link>
  <link name="add_1">
    <!--- small-pics -->
    <visual>
      <geometry>
        <mesh filename="/home/ewenwan/ewenwan/learn/learn_ros_urdf/UArmForROS/urdf/daes/add_1.dae"/>
        <!---
        <cylinder length="0.05" radius="0.005"/>  <! 0.05 0.005 -->
      </geometry>
      <origin rpy=" 0 1.57 0" xyz="0.0 0 0"/>
      <!--- 0 0 0.025 -->
      <material name="inwhite">

	  </material>
    </visual>
  </link>
  <link name="add_4">
    <!--- triangle -->
    <visual>
      <geometry>
        <mesh filename="/home/ewenwan/ewenwan/learn/learn_ros_urdf/UArmForROS/urdf/daes/add_4.dae"/>
        <!---
        <cylinder length="0.05" radius="0.005"/>  <! 0.05 0.005 -->
      </geometry>
      <origin rpy=" 0 1.57 1.57" xyz="0.0 0 0"/>
      <!--- 0 0 0.025 -->
      <material name="inwhite">

	  </material>
    </visual>
  </link>
  <link name="add_2">
    <!--- triangle -->
    <visual>
      <geometry>
        <mesh filename="/home/ewenwan/ewenwan/learn/learn_ros_urdf/UArmForROS/urdf/daes/add_2.dae"/>
        <!---
        <cylinder length="0.05" radius="0.005"/>  <! 0.05 0.005 -->
      </geometry>
      <origin rpy=" 1.57 1.57 0 " xyz="0.0 0 0"/>
      <!--- 0 0 0.025 -->
      <material name="inwhite">

	  </material>
    </visual>
  </link>
  <link name="add_3">
    <!--- triangle -->
    <visual>
      <geometry>
        <mesh filename="/home/ewenwan/ewenwan/learn/learn_ros_urdf/UArmForROS/urdf/daes/add_3.dae"/>
        <!---
        <cylinder length="0.05" radius="0.005"/>  <! 0.05 0.005 -->
      </geometry>
      <origin rpy=" 1.57 -1.57 1.57" xyz="0.0 0 0"/>
      <!--- 0 0 0.025 -->
      <material name="inwhite">

	  </material>
    </visual>
  </link>
  <link name="add_5">
    <!--- triangle -->
    <visual>
      <geometry>
        <mesh filename="/home/ewenwan/ewenwan/learn/learn_ros_urdf/UArmForROS/urdf/daes/add_5.dae"/>
        <!---
        <cylinder length="0.05" radius="0.005"/>  <! 0.05 0.005 -->
      </geometry>
      <origin rpy=" 1.57 -1.57 0" xyz="0.0 0 0"/>
      <!--- 0 0 0.025 -->
      <material name="inwhite">

	  </material>
    </visual>
  </link>
  <joint name="base_to_base_rot" type="revolute">
    <axis xyz="0 0 1"/>
    <limit effort="1000.0" lower="0.0" upper="3.14159" velocity="0"/>
    <parent link="base"/>
    <child link="base_rot"/>
    <origin rpy="0 0 0" xyz="0 0 0.032"/>
    <!--- 0 0 0.10645 -->
  </joint>
  <joint name="base_rot_to_link_1" type="revolute">
    <axis xyz="0 0 1"/>
    <limit effort="1000.0" lower="-0.5236" upper="2.356" velocity="0"/>
    <parent link="base_rot"/>
    <child link="link_1"/>
    <origin rpy="  1.57  0 0" xyz="0.02117 0 0.07345"/>
    <!--- 0.0212 0 0.006 -->
  </joint>
  <joint name="link_1_to_link_2" type="revolute">
    <axis xyz="0 0 1"/>
    <limit effort="1000.0" lower="-2.53" upper="2.53" velocity="0"/>
    <parent link="link_1"/>
    <child link="link_2"/>
    <origin rpy=" 0 0 0" xyz="0.14825 0  0 "/>
    <!--- 0.14 0  0 -->
  </joint>
  <joint name="link_2_to_link_3" type="revolute">
    <axis xyz="0 0 1"/>
    <limit effort="1000.0" lower="-2.53" upper="2.53" velocity="0"/>
    <parent link="link_2"/>
    <child link="link_3"/>
    <origin rpy=" 0 0 1.57" xyz="0.16 0.005 0"/>
    <!--- 0.16 0  0 -->
  </joint>
  <joint name="link_3_to_link_end" type="revolute">
    <axis xyz="0 0 1"/>
    <limit effort="1000.0" lower="0.0" upper="3.1416" velocity="0"/>
    <parent link="link_3"/>
    <child link="link_end"/>
    <origin rpy=" 0 1.57 0" xyz="-0.009 -0.0348 0"/>
    <!--- 0.02 0  0 -->
  </joint>
  <joint name="link_1_to_add_1" type="revolute">
    <axis xyz="0 0 1"/>
    <limit effort="1000.0" lower="-3.1416" upper="0" velocity="0"/>
    <parent link="link_1"/>
    <child link="add_1"/>
    <origin rpy=" 0 0 3.1416" xyz="0 0 0.00875"/>
    <!--- 0.02 0  0 -->
  </joint>
  <joint name="link_2_to_add_4" type="revolute">
    <axis xyz="0 0 1"/>
    <limit effort="1000.0" lower="-3.1416" upper="3.1416" velocity="0"/>
    <parent link="link_2"/>
    <child link="add_4"/>
    <origin rpy=" 0 0 0" xyz="0 0 -0.0136"/>
    <!--- 0.02 0  0 -->
  </joint>
  <joint name="link_3_to_add_2" type="revolute">
    <axis xyz="0 0 1"/>
    <limit effort="1000.0" lower="-1.57" upper="2.356" velocity="0"/>
    <parent link="link_3"/>
    <child link="add_2"/>
    <origin rpy=" 0 0 1.57" xyz="0.02022 -0.03367 -0.01751"/>
    <!--- 0.02 0  0 -->
  </joint>
  <joint name="base_rot_to_add_3" type="revolute">
    <axis xyz="0 0 1"/>
    <limit effort="1000.0" lower="-1.57" upper="3.1416" velocity="0"/>
    <parent link="base_rot"/>
    <child link="add_3"/>
    <origin rpy=" -1.57  0 3.1416" xyz="-0.01 0.022 0.09783"/>
    <!--- 0.0212 0 0.006 -->
  </joint>
  <joint name="link_2_to_add_5" type="revolute">
    <axis xyz="0 0 1"/>
    <limit effort="1000.0" lower="-1.57" upper="1.57" velocity="0"/>
    <parent link="link_2"/>
    <child link="add_5"/>
    <origin rpy=" 0 0 0" xyz="-0.054 0.005 0.0129"/>
    <!--- 0.02 0  0 -->
  </joint>
</robot>

